Traceback (most recent call last):
  File "/CARE-U/depthai-python/examples/calibration_backup-AREL.py", line 19, in <module>
    with dai.Device() as device:
RuntimeError: Failed to find device after booting, error message: X_LINK_DEVICE_NOT_FOUND
Connected!
Command execution successful
Traceback (most recent call last):
  File "/CARE-U/depthai-python/examples/encoding_max_limit-AREL.py", line 68, in <module>
    with dai.Device(pipeline) as dev:
RuntimeError: No available devices
Connected!
Command execution successful
Traceback (most recent call last):
  File "/CARE-U/depthai-python/examples/encoding_max_limit-AREL.py", line 68, in <module>
    with dai.Device(pipeline) as dev:
RuntimeError: No available devices
Connected!
Command execution successful
Traceback (most recent call last):
  File "/CARE-U/depthai-python/examples/encoding_max_limit-AREL.py", line 68, in <module>
    with dai.Device(pipeline) as dev:
RuntimeError: No available devices
Connected!
Command execution successful
Traceback (most recent call last):
  File "/CARE-U/depthai-python/examples/encoding_max_limit-AREL.py", line 68, in <module>
    with dai.Device(pipeline) as dev:
RuntimeError: No available devices
Connected!
Command execution successful
Traceback (most recent call last):
  File "/CARE-U/depthai-python/examples/encoding_max_limit-AREL.py", line 68, in <module>
    with dai.Device(pipeline) as dev:
RuntimeError: No available devices
Connected!
Command execution successful
Traceback (most recent call last):
  File "/CARE-U/depthai-python/examples/encoding_max_limit-AREL.py", line 68, in <module>
    with dai.Device(pipeline) as dev:
RuntimeError: No available devices
Connected!
Command execution successful
Traceback (most recent call last):
  File "/CARE-U/depthai-python/examples/encoding_max_limit-AREL.py", line 68, in <module>
    with dai.Device(pipeline) as dev:
RuntimeError: No available devices
Connected!
Command execution successful
Traceback (most recent call last):
  File "/CARE-U/depthai-python/examples/encoding_max_limit-AREL.py", line 68, in <module>
    with dai.Device(pipeline) as dev:
RuntimeError: No available devices
Connected!
Command execution successful
Traceback (most recent call last):
  File "/CARE-U/depthai-python/examples/encoding_max_limit-AREL.py", line 68, in <module>
    with dai.Device(pipeline) as dev:
RuntimeError: No available devices
/CARE-U/AREL-record.sh: line 77: uhubctl: command not found
Connected!
Command execution successful
