Calibration Data on the device is backed up at:
/CARE-U/recordings/2021-07-14-150451/depthai_calib.json
Connected!
Command execution successful
Will loop for 70 seconds
Traceback (most recent call last):
  File "/CARE-U/depthai-python/examples/encoding_max_limit-AREL.py", line 86, in <module>
    while outQ2.has():
RuntimeError: Communication exception - possible device error/misconfiguration. Original message 'Couldn't read data from stream: 've2Out' (X_LINK_ERROR)'
Will loop for 70 seconds
Traceback (most recent call last):
  File "/CARE-U/depthai-python/examples/encoding_max_limit-AREL.py", line 86, in <module>
    while outQ2.has():
RuntimeError: Communication exception - possible device error/misconfiguration. Original message 'Couldn't read data from stream: 've2Out' (X_LINK_ERROR)'
Current status for hub 2 [1d6b:0003 Linux 5.8.0-1024-raspi xhci-hcd xHCI Host Controller 0000:01:00.0, USB 3.00, 4 ports]
  Port 1: 02a0 power 5gbps Rx.Detect
  Port 2: 02b0 power 5gbps Rx.Detect reset
  Port 3: 02a0 power 5gbps Rx.Detect
  Port 4: 02a0 power 5gbps Rx.Detect
Sent power off request
New status for hub 2 [1d6b:0003 Linux 5.8.0-1024-raspi xhci-hcd xHCI Host Controller 0000:01:00.0, USB 3.00, 4 ports]
  Port 1: 0080 off
  Port 2: 0080 off
  Port 3: 0080 off
  Port 4: 0080 off
Current status for hub 1-1 [2109:3431 USB2.0 Hub, USB 2.10, 4 ports]
  Port 1: 0100 power
  Port 2: 0503 power highspeed enable connect [03e7:2485 Movidius Ltd. Movidius MyriadX 03e72485]
  Port 3: 0100 power
  Port 4: 0100 power
Sent power off request
New status for hub 1-1 [2109:3431 USB2.0 Hub, USB 2.10, 4 ports]
  Port 1: 0000 off
  Port 2: 0000 off
  Port 3: 0000 off
  Port 4: 0000 off
