Calibration Data on the device is backed up at:
/CARE-U/recordings/2021-07-14-152113/depthai_calib.json
Connected!
Command execution successful
Will loop for 5 seconds
Traceback (most recent call last):
  File "/CARE-U/depthai-python/examples/encoding_max_limit-AREL.py", line 86, in <module>
    while outQ2.has():
RuntimeError: Communication exception - possible device error/misconfiguration. Original message 'Couldn't read data from stream: 've2Out' (X_LINK_ERROR)'
Connected!
Command execution successful
Will loop for 5 seconds
To view the encoded data, convert the stream file (.h264/.h265) into a video file (.mp4), using commands below:
ffmpeg -framerate 15 -i mono1.h264 -c copy mono1.mp4
ffmpeg -framerate 15 -i mono2.h264 -c copy mono2.mp4
ffmpeg -framerate 15 -i color.h265 -c copy color.mp4
Connected!
Command execution successful
Will loop for 5 seconds
To view the encoded data, convert the stream file (.h264/.h265) into a video file (.mp4), using commands below:
ffmpeg -framerate 15 -i mono1.h264 -c copy mono1.mp4
ffmpeg -framerate 15 -i mono2.h264 -c copy mono2.mp4
ffmpeg -framerate 15 -i color.h265 -c copy color.mp4
Connected!
Command execution successful
Will loop for 5 seconds
Traceback (most recent call last):
  File "/CARE-U/depthai-python/examples/encoding_max_limit-AREL.py", line 89, in <module>
    while outQ3.has():
RuntimeError: Communication exception - possible device error/misconfiguration. Original message 'Couldn't read data from stream: 've3Out' (X_LINK_ERROR)'
Connected!
Command execution successful
Will loop for 5 seconds
To view the encoded data, convert the stream file (.h264/.h265) into a video file (.mp4), using commands below:
ffmpeg -framerate 15 -i mono1.h264 -c copy mono1.mp4
ffmpeg -framerate 15 -i mono2.h264 -c copy mono2.mp4
ffmpeg -framerate 15 -i color.h265 -c copy color.mp4
Connected!
Command execution successful
Will loop for 5 seconds
Traceback (most recent call last):
  File "/CARE-U/depthai-python/examples/encoding_max_limit-AREL.py", line 89, in <module>
    while outQ3.has():
RuntimeError: Communication exception - possible device error/misconfiguration. Original message 'Couldn't read data from stream: 've3Out' (X_LINK_ERROR)'
Connected!
Command execution successful
Will loop for 5 seconds
Traceback (most recent call last):
  File "/CARE-U/depthai-python/examples/encoding_max_limit-AREL.py", line 86, in <module>
    while outQ2.has():
RuntimeError: Communication exception - possible device error/misconfiguration. Original message 'Couldn't read data from stream: 've2Out' (X_LINK_ERROR)'
Connected!
Command execution successful
Connected!
Command execution successful
terminate called after throwing an instance of 'std::runtime_error'
  what():  Couldn't read data from stream: '__timesync' (X_LINK_ERROR)
Connected!
Command execution successful
